INFO 2024-01-16 00:28:49,396 autoreload Watching for file changes with StatReloader
INFO 2024-01-16 22:38:48,475 autoreload Watching for file changes with StatReloader
INFO 2024-01-16 22:40:39,541 autoreload C:\Users\Semen\Documents\Проекты\Skillfactory\news2\venv\project\simpleapp\views.py changed, reloading.
INFO 2024-01-16 22:40:42,353 autoreload Watching for file changes with StatReloader
INFO 2024-01-16 22:41:08,873 autoreload C:\Users\Semen\Documents\Проекты\Skillfactory\news2\venv\project\simpleapp\views.py changed, reloading.
INFO 2024-01-16 22:41:12,190 autoreload Watching for file changes with StatReloader
INFO 2024-01-16 22:41:33,448 autoreload C:\Users\Semen\Documents\Проекты\Skillfactory\news2\venv\project\simpleapp\views.py changed, reloading.
INFO 2024-01-16 22:41:34,081 autoreload Watching for file changes with StatReloader
INFO 2024-01-16 22:41:37,714 autoreload Watching for file changes with StatReloader
INFO 2024-01-16 22:52:15,861 autoreload C:\Users\Semen\Documents\Проекты\Skillfactory\news2\venv\project\simpleapp\views.py changed, reloading.
INFO 2024-01-16 22:52:16,553 autoreload Watching for file changes with StatReloader
INFO 2024-01-16 22:52:21,899 autoreload Watching for file changes with StatReloader
ERROR 2024-01-16 22:53:31,809 log Internal Server Error: /subscribe/
Traceback (most recent call last):
  File "C:\Users\Semen\Documents\Проекты\Skillfactory\news2\venv\lib\site-packages\django\core\handlers\exception.py", line 55, in inner
    response = get_response(request)
  File "C:\Users\Semen\Documents\Проекты\Skillfactory\news2\venv\lib\site-packages\django\core\handlers\base.py", line 197, in _get_response
    response = wrapped_callback(request, *callback_args, **callback_kwargs)
  File "C:\Users\Semen\Documents\Проекты\Skillfactory\news2\venv\lib\site-packages\django\views\generic\base.py", line 104, in view
    return self.dispatch(request, *args, **kwargs)
  File "C:\Users\Semen\Documents\Проекты\Skillfactory\news2\venv\lib\site-packages\django\views\generic\base.py", line 143, in dispatch
    return handler(request, *args, **kwargs)
  File "C:\Users\Semen\Documents\Проекты\Skillfactory\news2\venv\lib\site-packages\django\views\generic\edit.py", line 180, in get
    return super().get(request, *args, **kwargs)
  File "C:\Users\Semen\Documents\Проекты\Skillfactory\news2\venv\lib\site-packages\django\views\generic\edit.py", line 144, in get
    return self.render_to_response(self.get_context_data())
  File "C:\Users\Semen\Documents\Проекты\Skillfactory\news2\venv\lib\site-packages\django\views\generic\edit.py", line 74, in get_context_data
    kwargs["form"] = self.get_form()
  File "C:\Users\Semen\Documents\Проекты\Skillfactory\news2\venv\lib\site-packages\django\views\generic\edit.py", line 39, in get_form
    return form_class(**self.get_form_kwargs())
TypeError: BaseModelForm.__init__() got an unexpected keyword argument 'user'
WARNING 2024-01-16 23:00:18,001 log Forbidden (CSRF token from POST incorrect.): /accounts/login/
ERROR 2024-01-16 23:00:56,258 log Internal Server Error: /subscribe/
Traceback (most recent call last):
  File "C:\Users\Semen\Documents\Проекты\Skillfactory\news2\venv\lib\site-packages\django\core\handlers\exception.py", line 55, in inner
    response = get_response(request)
  File "C:\Users\Semen\Documents\Проекты\Skillfactory\news2\venv\lib\site-packages\django\core\handlers\base.py", line 197, in _get_response
    response = wrapped_callback(request, *callback_args, **callback_kwargs)
  File "C:\Users\Semen\Documents\Проекты\Skillfactory\news2\venv\lib\site-packages\django\views\generic\base.py", line 104, in view
    return self.dispatch(request, *args, **kwargs)
  File "C:\Users\Semen\Documents\Проекты\Skillfactory\news2\venv\lib\site-packages\django\views\generic\base.py", line 143, in dispatch
    return handler(request, *args, **kwargs)
  File "C:\Users\Semen\Documents\Проекты\Skillfactory\news2\venv\lib\site-packages\django\views\generic\edit.py", line 180, in get
    return super().get(request, *args, **kwargs)
  File "C:\Users\Semen\Documents\Проекты\Skillfactory\news2\venv\lib\site-packages\django\views\generic\edit.py", line 144, in get
    return self.render_to_response(self.get_context_data())
  File "C:\Users\Semen\Documents\Проекты\Skillfactory\news2\venv\lib\site-packages\django\views\generic\edit.py", line 74, in get_context_data
    kwargs["form"] = self.get_form()
  File "C:\Users\Semen\Documents\Проекты\Skillfactory\news2\venv\lib\site-packages\django\views\generic\edit.py", line 39, in get_form
    return form_class(**self.get_form_kwargs())
TypeError: BaseModelForm.__init__() got an unexpected keyword argument 'user'
ERROR 2024-01-16 23:04:50,691 log Internal Server Error: /subscribe/
Traceback (most recent call last):
  File "C:\Users\Semen\Documents\Проекты\Skillfactory\news2\venv\lib\site-packages\django\core\handlers\exception.py", line 55, in inner
    response = get_response(request)
  File "C:\Users\Semen\Documents\Проекты\Skillfactory\news2\venv\lib\site-packages\django\core\handlers\base.py", line 197, in _get_response
    response = wrapped_callback(request, *callback_args, **callback_kwargs)
  File "C:\Users\Semen\Documents\Проекты\Skillfactory\news2\venv\lib\site-packages\django\views\generic\base.py", line 104, in view
    return self.dispatch(request, *args, **kwargs)
  File "C:\Users\Semen\Documents\Проекты\Skillfactory\news2\venv\lib\site-packages\django\views\generic\base.py", line 143, in dispatch
    return handler(request, *args, **kwargs)
  File "C:\Users\Semen\Documents\Проекты\Skillfactory\news2\venv\lib\site-packages\django\views\generic\edit.py", line 180, in get
    return super().get(request, *args, **kwargs)
  File "C:\Users\Semen\Documents\Проекты\Skillfactory\news2\venv\lib\site-packages\django\views\generic\edit.py", line 144, in get
    return self.render_to_response(self.get_context_data())
  File "C:\Users\Semen\Documents\Проекты\Skillfactory\news2\venv\lib\site-packages\django\views\generic\edit.py", line 74, in get_context_data
    kwargs["form"] = self.get_form()
  File "C:\Users\Semen\Documents\Проекты\Skillfactory\news2\venv\lib\site-packages\django\views\generic\edit.py", line 39, in get_form
    return form_class(**self.get_form_kwargs())
TypeError: BaseModelForm.__init__() got an unexpected keyword argument 'user'
ERROR 2024-01-16 23:04:55,471 log Internal Server Error: /subscribe/
Traceback (most recent call last):
  File "C:\Users\Semen\Documents\Проекты\Skillfactory\news2\venv\lib\site-packages\django\core\handlers\exception.py", line 55, in inner
    response = get_response(request)
  File "C:\Users\Semen\Documents\Проекты\Skillfactory\news2\venv\lib\site-packages\django\core\handlers\base.py", line 197, in _get_response
    response = wrapped_callback(request, *callback_args, **callback_kwargs)
  File "C:\Users\Semen\Documents\Проекты\Skillfactory\news2\venv\lib\site-packages\django\views\generic\base.py", line 104, in view
    return self.dispatch(request, *args, **kwargs)
  File "C:\Users\Semen\Documents\Проекты\Skillfactory\news2\venv\lib\site-packages\django\views\generic\base.py", line 143, in dispatch
    return handler(request, *args, **kwargs)
  File "C:\Users\Semen\Documents\Проекты\Skillfactory\news2\venv\lib\site-packages\django\views\generic\edit.py", line 180, in get
    return super().get(request, *args, **kwargs)
  File "C:\Users\Semen\Documents\Проекты\Skillfactory\news2\venv\lib\site-packages\django\views\generic\edit.py", line 144, in get
    return self.render_to_response(self.get_context_data())
  File "C:\Users\Semen\Documents\Проекты\Skillfactory\news2\venv\lib\site-packages\django\views\generic\edit.py", line 74, in get_context_data
    kwargs["form"] = self.get_form()
  File "C:\Users\Semen\Documents\Проекты\Skillfactory\news2\venv\lib\site-packages\django\views\generic\edit.py", line 39, in get_form
    return form_class(**self.get_form_kwargs())
TypeError: BaseModelForm.__init__() got an unexpected keyword argument 'user'
INFO 2024-01-16 23:05:35,461 autoreload C:\Users\Semen\Documents\Проекты\Skillfactory\news2\venv\project\simpleapp\views.py changed, reloading.
INFO 2024-01-16 23:05:36,121 autoreload Watching for file changes with StatReloader
ERROR 2024-01-16 23:05:39,452 log Internal Server Error: /subscribe/
Traceback (most recent call last):
  File "C:\Users\Semen\Documents\Проекты\Skillfactory\news2\venv\lib\site-packages\django\core\handlers\exception.py", line 55, in inner
    response = get_response(request)
  File "C:\Users\Semen\Documents\Проекты\Skillfactory\news2\venv\lib\site-packages\django\core\handlers\base.py", line 197, in _get_response
    response = wrapped_callback(request, *callback_args, **callback_kwargs)
  File "C:\Users\Semen\Documents\Проекты\Skillfactory\news2\venv\lib\site-packages\django\views\generic\base.py", line 104, in view
    return self.dispatch(request, *args, **kwargs)
  File "C:\Users\Semen\Documents\Проекты\Skillfactory\news2\venv\lib\site-packages\django\views\generic\base.py", line 143, in dispatch
    return handler(request, *args, **kwargs)
  File "C:\Users\Semen\Documents\Проекты\Skillfactory\news2\venv\lib\site-packages\django\views\generic\edit.py", line 180, in get
    return super().get(request, *args, **kwargs)
  File "C:\Users\Semen\Documents\Проекты\Skillfactory\news2\venv\lib\site-packages\django\views\generic\edit.py", line 144, in get
    return self.render_to_response(self.get_context_data())
  File "C:\Users\Semen\Documents\Проекты\Skillfactory\news2\venv\lib\site-packages\django\views\generic\edit.py", line 74, in get_context_data
    kwargs["form"] = self.get_form()
  File "C:\Users\Semen\Documents\Проекты\Skillfactory\news2\venv\lib\site-packages\django\views\generic\edit.py", line 39, in get_form
    return form_class(**self.get_form_kwargs())
TypeError: BaseModelForm.__init__() got an unexpected keyword argument 'user'
ERROR 2024-01-16 23:05:47,397 log Internal Server Error: /subscribe/
Traceback (most recent call last):
  File "C:\Users\Semen\Documents\Проекты\Skillfactory\news2\venv\lib\site-packages\django\core\handlers\exception.py", line 55, in inner
    response = get_response(request)
  File "C:\Users\Semen\Documents\Проекты\Skillfactory\news2\venv\lib\site-packages\django\core\handlers\base.py", line 197, in _get_response
    response = wrapped_callback(request, *callback_args, **callback_kwargs)
  File "C:\Users\Semen\Documents\Проекты\Skillfactory\news2\venv\lib\site-packages\django\views\generic\base.py", line 104, in view
    return self.dispatch(request, *args, **kwargs)
  File "C:\Users\Semen\Documents\Проекты\Skillfactory\news2\venv\lib\site-packages\django\views\generic\base.py", line 143, in dispatch
    return handler(request, *args, **kwargs)
  File "C:\Users\Semen\Documents\Проекты\Skillfactory\news2\venv\lib\site-packages\django\views\generic\edit.py", line 180, in get
    return super().get(request, *args, **kwargs)
  File "C:\Users\Semen\Documents\Проекты\Skillfactory\news2\venv\lib\site-packages\django\views\generic\edit.py", line 144, in get
    return self.render_to_response(self.get_context_data())
  File "C:\Users\Semen\Documents\Проекты\Skillfactory\news2\venv\lib\site-packages\django\views\generic\edit.py", line 74, in get_context_data
    kwargs["form"] = self.get_form()
  File "C:\Users\Semen\Documents\Проекты\Skillfactory\news2\venv\lib\site-packages\django\views\generic\edit.py", line 39, in get_form
    return form_class(**self.get_form_kwargs())
TypeError: BaseModelForm.__init__() got an unexpected keyword argument 'user'
ERROR 2024-01-16 23:06:08,578 log Internal Server Error: /subscribe/
Traceback (most recent call last):
  File "C:\Users\Semen\Documents\Проекты\Skillfactory\news2\venv\lib\site-packages\django\core\handlers\exception.py", line 55, in inner
    response = get_response(request)
  File "C:\Users\Semen\Documents\Проекты\Skillfactory\news2\venv\lib\site-packages\django\core\handlers\base.py", line 197, in _get_response
    response = wrapped_callback(request, *callback_args, **callback_kwargs)
  File "C:\Users\Semen\Documents\Проекты\Skillfactory\news2\venv\lib\site-packages\django\views\generic\base.py", line 104, in view
    return self.dispatch(request, *args, **kwargs)
  File "C:\Users\Semen\Documents\Проекты\Skillfactory\news2\venv\lib\site-packages\django\views\generic\base.py", line 143, in dispatch
    return handler(request, *args, **kwargs)
  File "C:\Users\Semen\Documents\Проекты\Skillfactory\news2\venv\lib\site-packages\django\views\generic\edit.py", line 180, in get
    return super().get(request, *args, **kwargs)
  File "C:\Users\Semen\Documents\Проекты\Skillfactory\news2\venv\lib\site-packages\django\views\generic\edit.py", line 144, in get
    return self.render_to_response(self.get_context_data())
  File "C:\Users\Semen\Documents\Проекты\Skillfactory\news2\venv\lib\site-packages\django\views\generic\edit.py", line 74, in get_context_data
    kwargs["form"] = self.get_form()
  File "C:\Users\Semen\Documents\Проекты\Skillfactory\news2\venv\lib\site-packages\django\views\generic\edit.py", line 39, in get_form
    return form_class(**self.get_form_kwargs())
TypeError: BaseModelForm.__init__() got an unexpected keyword argument 'user'
INFO 2024-01-16 23:06:09,118 autoreload C:\Users\Semen\Documents\Проекты\Skillfactory\news2\venv\project\simpleapp\views.py changed, reloading.
INFO 2024-01-16 23:06:09,786 autoreload Watching for file changes with StatReloader
ERROR 2024-01-16 23:06:13,370 log Internal Server Error: /subscribe/
Traceback (most recent call last):
  File "C:\Users\Semen\Documents\Проекты\Skillfactory\news2\venv\lib\site-packages\django\core\handlers\exception.py", line 55, in inner
    response = get_response(request)
  File "C:\Users\Semen\Documents\Проекты\Skillfactory\news2\venv\lib\site-packages\django\core\handlers\base.py", line 197, in _get_response
    response = wrapped_callback(request, *callback_args, **callback_kwargs)
  File "C:\Users\Semen\Documents\Проекты\Skillfactory\news2\venv\lib\site-packages\django\views\generic\base.py", line 104, in view
    return self.dispatch(request, *args, **kwargs)
  File "C:\Users\Semen\Documents\Проекты\Skillfactory\news2\venv\lib\site-packages\django\views\generic\base.py", line 143, in dispatch
    return handler(request, *args, **kwargs)
  File "C:\Users\Semen\Documents\Проекты\Skillfactory\news2\venv\lib\site-packages\django\views\generic\edit.py", line 180, in get
    return super().get(request, *args, **kwargs)
  File "C:\Users\Semen\Documents\Проекты\Skillfactory\news2\venv\lib\site-packages\django\views\generic\edit.py", line 144, in get
    return self.render_to_response(self.get_context_data())
  File "C:\Users\Semen\Documents\Проекты\Skillfactory\news2\venv\lib\site-packages\django\views\generic\edit.py", line 74, in get_context_data
    kwargs["form"] = self.get_form()
  File "C:\Users\Semen\Documents\Проекты\Skillfactory\news2\venv\lib\site-packages\django\views\generic\edit.py", line 39, in get_form
    return form_class(**self.get_form_kwargs())
TypeError: BaseModelForm.__init__() got an unexpected keyword argument 'user'
ERROR 2024-01-16 23:06:16,952 log Internal Server Error: /subscribe/
Traceback (most recent call last):
  File "C:\Users\Semen\Documents\Проекты\Skillfactory\news2\venv\lib\site-packages\django\core\handlers\exception.py", line 55, in inner
    response = get_response(request)
  File "C:\Users\Semen\Documents\Проекты\Skillfactory\news2\venv\lib\site-packages\django\core\handlers\base.py", line 197, in _get_response
    response = wrapped_callback(request, *callback_args, **callback_kwargs)
  File "C:\Users\Semen\Documents\Проекты\Skillfactory\news2\venv\lib\site-packages\django\views\generic\base.py", line 104, in view
    return self.dispatch(request, *args, **kwargs)
  File "C:\Users\Semen\Documents\Проекты\Skillfactory\news2\venv\lib\site-packages\django\views\generic\base.py", line 143, in dispatch
    return handler(request, *args, **kwargs)
  File "C:\Users\Semen\Documents\Проекты\Skillfactory\news2\venv\lib\site-packages\django\views\generic\edit.py", line 180, in get
    return super().get(request, *args, **kwargs)
  File "C:\Users\Semen\Documents\Проекты\Skillfactory\news2\venv\lib\site-packages\django\views\generic\edit.py", line 144, in get
    return self.render_to_response(self.get_context_data())
  File "C:\Users\Semen\Documents\Проекты\Skillfactory\news2\venv\lib\site-packages\django\views\generic\edit.py", line 74, in get_context_data
    kwargs["form"] = self.get_form()
  File "C:\Users\Semen\Documents\Проекты\Skillfactory\news2\venv\lib\site-packages\django\views\generic\edit.py", line 39, in get_form
    return form_class(**self.get_form_kwargs())
TypeError: BaseModelForm.__init__() got an unexpected keyword argument 'user'
INFO 2024-01-16 23:06:28,839 autoreload C:\Users\Semen\Documents\Проекты\Skillfactory\news2\venv\project\simpleapp\forms.py changed, reloading.
INFO 2024-01-16 23:06:29,487 autoreload Watching for file changes with StatReloader
INFO 2024-01-16 23:08:36,605 autoreload C:\Users\Semen\Documents\Проекты\Skillfactory\news2\venv\project\simpleapp\forms.py changed, reloading.
INFO 2024-01-16 23:08:37,246 autoreload Watching for file changes with StatReloader
ERROR 2024-01-16 23:08:40,923 log Internal Server Error: /subscribe/
Traceback (most recent call last):
  File "C:\Users\Semen\Documents\Проекты\Skillfactory\news2\venv\lib\site-packages\django\core\handlers\exception.py", line 55, in inner
    response = get_response(request)
  File "C:\Users\Semen\Documents\Проекты\Skillfactory\news2\venv\lib\site-packages\django\core\handlers\base.py", line 197, in _get_response
    response = wrapped_callback(request, *callback_args, **callback_kwargs)
  File "C:\Users\Semen\Documents\Проекты\Skillfactory\news2\venv\lib\site-packages\django\views\generic\base.py", line 104, in view
    return self.dispatch(request, *args, **kwargs)
  File "C:\Users\Semen\Documents\Проекты\Skillfactory\news2\venv\lib\site-packages\django\views\generic\base.py", line 143, in dispatch
    return handler(request, *args, **kwargs)
  File "C:\Users\Semen\Documents\Проекты\Skillfactory\news2\venv\lib\site-packages\django\views\generic\edit.py", line 180, in get
    return super().get(request, *args, **kwargs)
  File "C:\Users\Semen\Documents\Проекты\Skillfactory\news2\venv\lib\site-packages\django\views\generic\edit.py", line 144, in get
    return self.render_to_response(self.get_context_data())
  File "C:\Users\Semen\Documents\Проекты\Skillfactory\news2\venv\lib\site-packages\django\views\generic\edit.py", line 74, in get_context_data
    kwargs["form"] = self.get_form()
  File "C:\Users\Semen\Documents\Проекты\Skillfactory\news2\venv\lib\site-packages\django\views\generic\edit.py", line 39, in get_form
    return form_class(**self.get_form_kwargs())
TypeError: BaseModelForm.__init__() got an unexpected keyword argument 'user'
INFO 2024-01-16 23:10:03,584 autoreload C:\Users\Semen\Documents\Проекты\Skillfactory\news2\venv\project\simpleapp\views.py changed, reloading.
INFO 2024-01-16 23:10:04,318 autoreload Watching for file changes with StatReloader
INFO 2024-01-16 23:12:17,516 autoreload C:\Users\Semen\Documents\Проекты\Skillfactory\news2\venv\project\simpleapp\forms.py changed, reloading.
INFO 2024-01-16 23:12:18,310 autoreload Watching for file changes with StatReloader
INFO 2024-01-16 23:12:52,996 autoreload C:\Users\Semen\Documents\Проекты\Skillfactory\news2\venv\project\simpleapp\forms.py changed, reloading.
INFO 2024-01-16 23:12:53,795 autoreload Watching for file changes with StatReloader
INFO 2024-01-16 23:15:18,646 autoreload C:\Users\Semen\Documents\Проекты\Skillfactory\news2\venv\project\simpleapp\views.py changed, reloading.
INFO 2024-01-16 23:15:19,291 autoreload Watching for file changes with StatReloader
ERROR 2024-01-16 23:15:32,241 log Internal Server Error: /subscribe/
Traceback (most recent call last):
  File "C:\Users\Semen\Documents\Проекты\Skillfactory\news2\venv\lib\site-packages\django\core\handlers\exception.py", line 55, in inner
    response = get_response(request)
  File "C:\Users\Semen\Documents\Проекты\Skillfactory\news2\venv\lib\site-packages\django\core\handlers\base.py", line 197, in _get_response
    response = wrapped_callback(request, *callback_args, **callback_kwargs)
  File "C:\Users\Semen\Documents\Проекты\Skillfactory\news2\venv\lib\site-packages\django\views\generic\base.py", line 104, in view
    return self.dispatch(request, *args, **kwargs)
  File "C:\Users\Semen\Documents\Проекты\Skillfactory\news2\venv\lib\site-packages\django\views\generic\base.py", line 143, in dispatch
    return handler(request, *args, **kwargs)
  File "C:\Users\Semen\Documents\Проекты\Skillfactory\news2\venv\lib\site-packages\django\views\generic\edit.py", line 180, in get
    return super().get(request, *args, **kwargs)
  File "C:\Users\Semen\Documents\Проекты\Skillfactory\news2\venv\lib\site-packages\django\views\generic\edit.py", line 144, in get
    return self.render_to_response(self.get_context_data())
  File "C:\Users\Semen\Documents\Проекты\Skillfactory\news2\venv\lib\site-packages\django\views\generic\edit.py", line 74, in get_context_data
    kwargs["form"] = self.get_form()
  File "C:\Users\Semen\Documents\Проекты\Skillfactory\news2\venv\lib\site-packages\django\views\generic\edit.py", line 39, in get_form
    return form_class(**self.get_form_kwargs())
TypeError: BaseModelForm.__init__() got an unexpected keyword argument 'user'
INFO 2024-01-16 23:18:26,899 autoreload C:\Users\Semen\Documents\Проекты\Skillfactory\news2\venv\project\simpleapp\mixins.py changed, reloading.
INFO 2024-01-16 23:18:27,662 autoreload Watching for file changes with StatReloader
INFO 2024-01-16 23:18:34,304 autoreload C:\Users\Semen\Documents\Проекты\Skillfactory\news2\venv\project\simpleapp\mixins.py changed, reloading.
INFO 2024-01-16 23:18:34,959 autoreload Watching for file changes with StatReloader
INFO 2024-01-16 23:19:53,451 autoreload C:\Users\Semen\Documents\Проекты\Skillfactory\news2\venv\project\simpleapp\mixins.py changed, reloading.
INFO 2024-01-16 23:19:54,096 autoreload Watching for file changes with StatReloader
ERROR 2024-01-16 23:20:04,705 log Internal Server Error: /subscribe/
Traceback (most recent call last):
  File "C:\Users\Semen\Documents\Проекты\Skillfactory\news2\venv\lib\site-packages\django\core\handlers\exception.py", line 55, in inner
    response = get_response(request)
  File "C:\Users\Semen\Documents\Проекты\Skillfactory\news2\venv\lib\site-packages\django\core\handlers\base.py", line 197, in _get_response
    response = wrapped_callback(request, *callback_args, **callback_kwargs)
  File "C:\Users\Semen\Documents\Проекты\Skillfactory\news2\venv\lib\site-packages\django\views\generic\base.py", line 104, in view
    return self.dispatch(request, *args, **kwargs)
  File "C:\Users\Semen\Documents\Проекты\Skillfactory\news2\venv\lib\site-packages\django\views\generic\base.py", line 143, in dispatch
    return handler(request, *args, **kwargs)
  File "C:\Users\Semen\Documents\Проекты\Skillfactory\news2\venv\lib\site-packages\django\views\generic\edit.py", line 180, in get
    return super().get(request, *args, **kwargs)
  File "C:\Users\Semen\Documents\Проекты\Skillfactory\news2\venv\lib\site-packages\django\views\generic\edit.py", line 144, in get
    return self.render_to_response(self.get_context_data())
  File "C:\Users\Semen\Documents\Проекты\Skillfactory\news2\venv\lib\site-packages\django\views\generic\edit.py", line 74, in get_context_data
    kwargs["form"] = self.get_form()
  File "C:\Users\Semen\Documents\Проекты\Skillfactory\news2\venv\lib\site-packages\django\views\generic\edit.py", line 39, in get_form
    return form_class(**self.get_form_kwargs())
TypeError: BaseModelForm.__init__() got an unexpected keyword argument 'user'
INFO 2024-01-16 23:21:35,267 autoreload C:\Users\Semen\Documents\Проекты\Skillfactory\news2\venv\project\simpleapp\mixins.py changed, reloading.
INFO 2024-01-16 23:21:35,929 autoreload Watching for file changes with StatReloader
ERROR 2024-01-16 23:21:43,977 log Internal Server Error: /subscribe/
Traceback (most recent call last):
  File "C:\Users\Semen\Documents\Проекты\Skillfactory\news2\venv\lib\site-packages\django\core\handlers\exception.py", line 55, in inner
    response = get_response(request)
  File "C:\Users\Semen\Documents\Проекты\Skillfactory\news2\venv\lib\site-packages\django\core\handlers\base.py", line 197, in _get_response
    response = wrapped_callback(request, *callback_args, **callback_kwargs)
  File "C:\Users\Semen\Documents\Проекты\Skillfactory\news2\venv\lib\site-packages\django\views\generic\base.py", line 104, in view
    return self.dispatch(request, *args, **kwargs)
  File "C:\Users\Semen\Documents\Проекты\Skillfactory\news2\venv\lib\site-packages\django\views\generic\base.py", line 143, in dispatch
    return handler(request, *args, **kwargs)
  File "C:\Users\Semen\Documents\Проекты\Skillfactory\news2\venv\lib\site-packages\django\views\generic\edit.py", line 180, in get
    return super().get(request, *args, **kwargs)
  File "C:\Users\Semen\Documents\Проекты\Skillfactory\news2\venv\lib\site-packages\django\views\generic\edit.py", line 144, in get
    return self.render_to_response(self.get_context_data())
  File "C:\Users\Semen\Documents\Проекты\Skillfactory\news2\venv\lib\site-packages\django\views\generic\edit.py", line 74, in get_context_data
    kwargs["form"] = self.get_form()
  File "C:\Users\Semen\Documents\Проекты\Skillfactory\news2\venv\lib\site-packages\django\views\generic\edit.py", line 39, in get_form
    return form_class(**self.get_form_kwargs())
TypeError: BaseModelForm.__init__() got an unexpected keyword argument 'user'
ERROR 2024-01-16 23:21:50,160 log Internal Server Error: /subscribe/
Traceback (most recent call last):
  File "C:\Users\Semen\Documents\Проекты\Skillfactory\news2\venv\lib\site-packages\django\core\handlers\exception.py", line 55, in inner
    response = get_response(request)
  File "C:\Users\Semen\Documents\Проекты\Skillfactory\news2\venv\lib\site-packages\django\core\handlers\base.py", line 197, in _get_response
    response = wrapped_callback(request, *callback_args, **callback_kwargs)
  File "C:\Users\Semen\Documents\Проекты\Skillfactory\news2\venv\lib\site-packages\django\views\generic\base.py", line 104, in view
    return self.dispatch(request, *args, **kwargs)
  File "C:\Users\Semen\Documents\Проекты\Skillfactory\news2\venv\lib\site-packages\django\views\generic\base.py", line 143, in dispatch
    return handler(request, *args, **kwargs)
  File "C:\Users\Semen\Documents\Проекты\Skillfactory\news2\venv\lib\site-packages\django\views\generic\edit.py", line 180, in get
    return super().get(request, *args, **kwargs)
  File "C:\Users\Semen\Documents\Проекты\Skillfactory\news2\venv\lib\site-packages\django\views\generic\edit.py", line 144, in get
    return self.render_to_response(self.get_context_data())
  File "C:\Users\Semen\Documents\Проекты\Skillfactory\news2\venv\lib\site-packages\django\views\generic\edit.py", line 74, in get_context_data
    kwargs["form"] = self.get_form()
  File "C:\Users\Semen\Documents\Проекты\Skillfactory\news2\venv\lib\site-packages\django\views\generic\edit.py", line 39, in get_form
    return form_class(**self.get_form_kwargs())
TypeError: BaseModelForm.__init__() got an unexpected keyword argument 'user'
INFO 2024-01-16 23:39:41,444 autoreload C:\Users\Semen\Documents\Проекты\Skillfactory\news2\venv\project\simpleapp\views.py changed, reloading.
INFO 2024-01-16 23:39:42,220 autoreload Watching for file changes with StatReloader
ERROR 2024-01-16 23:39:49,912 log Internal Server Error: /subscribe/
Traceback (most recent call last):
  File "C:\Users\Semen\Documents\Проекты\Skillfactory\news2\venv\lib\site-packages\django\core\handlers\exception.py", line 55, in inner
    response = get_response(request)
  File "C:\Users\Semen\Documents\Проекты\Skillfactory\news2\venv\lib\site-packages\django\core\handlers\base.py", line 197, in _get_response
    response = wrapped_callback(request, *callback_args, **callback_kwargs)
  File "C:\Users\Semen\Documents\Проекты\Skillfactory\news2\venv\lib\site-packages\django\views\generic\base.py", line 104, in view
    return self.dispatch(request, *args, **kwargs)
  File "C:\Users\Semen\Documents\Проекты\Skillfactory\news2\venv\lib\site-packages\django\views\generic\base.py", line 143, in dispatch
    return handler(request, *args, **kwargs)
  File "C:\Users\Semen\Documents\Проекты\Skillfactory\news2\venv\lib\site-packages\django\views\generic\edit.py", line 180, in get
    return super().get(request, *args, **kwargs)
  File "C:\Users\Semen\Documents\Проекты\Skillfactory\news2\venv\lib\site-packages\django\views\generic\edit.py", line 144, in get
    return self.render_to_response(self.get_context_data())
  File "C:\Users\Semen\Documents\Проекты\Skillfactory\news2\venv\lib\site-packages\django\views\generic\edit.py", line 74, in get_context_data
    kwargs["form"] = self.get_form()
  File "C:\Users\Semen\Documents\Проекты\Skillfactory\news2\venv\lib\site-packages\django\views\generic\edit.py", line 39, in get_form
    return form_class(**self.get_form_kwargs())
TypeError: BaseModelForm.__init__() got an unexpected keyword argument 'user'
INFO 2024-01-16 23:40:20,420 autoreload C:\Users\Semen\Documents\Проекты\Skillfactory\news2\venv\project\simpleapp\views.py changed, reloading.
INFO 2024-01-16 23:40:21,091 autoreload Watching for file changes with StatReloader
ERROR 2024-01-16 23:40:24,189 log Internal Server Error: /subscribe/
Traceback (most recent call last):
  File "C:\Users\Semen\Documents\Проекты\Skillfactory\news2\venv\lib\site-packages\django\core\handlers\exception.py", line 55, in inner
    response = get_response(request)
  File "C:\Users\Semen\Documents\Проекты\Skillfactory\news2\venv\lib\site-packages\django\core\handlers\base.py", line 197, in _get_response
    response = wrapped_callback(request, *callback_args, **callback_kwargs)
  File "C:\Users\Semen\Documents\Проекты\Skillfactory\news2\venv\lib\site-packages\django\views\generic\base.py", line 104, in view
    return self.dispatch(request, *args, **kwargs)
  File "C:\Users\Semen\Documents\Проекты\Skillfactory\news2\venv\lib\site-packages\django\views\generic\base.py", line 143, in dispatch
    return handler(request, *args, **kwargs)
  File "C:\Users\Semen\Documents\Проекты\Skillfactory\news2\venv\lib\site-packages\django\views\generic\edit.py", line 180, in get
    return super().get(request, *args, **kwargs)
  File "C:\Users\Semen\Documents\Проекты\Skillfactory\news2\venv\lib\site-packages\django\views\generic\edit.py", line 144, in get
    return self.render_to_response(self.get_context_data())
  File "C:\Users\Semen\Documents\Проекты\Skillfactory\news2\venv\lib\site-packages\django\views\generic\edit.py", line 74, in get_context_data
    kwargs["form"] = self.get_form()
  File "C:\Users\Semen\Documents\Проекты\Skillfactory\news2\venv\lib\site-packages\django\views\generic\edit.py", line 39, in get_form
    return form_class(**self.get_form_kwargs())
TypeError: BaseModelForm.__init__() got an unexpected keyword argument 'user'
INFO 2024-01-16 23:45:16,059 autoreload C:\Users\Semen\Documents\Проекты\Skillfactory\news2\venv\project\simpleapp\forms.py changed, reloading.
INFO 2024-01-16 23:45:16,734 autoreload Watching for file changes with StatReloader
ERROR 2024-01-16 23:45:22,319 log Internal Server Error: /subscribe/
Traceback (most recent call last):
  File "C:\Users\Semen\Documents\Проекты\Skillfactory\news2\venv\lib\site-packages\django\core\handlers\exception.py", line 55, in inner
    response = get_response(request)
  File "C:\Users\Semen\Documents\Проекты\Skillfactory\news2\venv\lib\site-packages\django\core\handlers\base.py", line 197, in _get_response
    response = wrapped_callback(request, *callback_args, **callback_kwargs)
  File "C:\Users\Semen\Documents\Проекты\Skillfactory\news2\venv\lib\site-packages\django\views\generic\base.py", line 104, in view
    return self.dispatch(request, *args, **kwargs)
  File "C:\Users\Semen\Documents\Проекты\Skillfactory\news2\venv\lib\site-packages\django\views\generic\base.py", line 143, in dispatch
    return handler(request, *args, **kwargs)
  File "C:\Users\Semen\Documents\Проекты\Skillfactory\news2\venv\lib\site-packages\django\views\generic\edit.py", line 180, in get
    return super().get(request, *args, **kwargs)
  File "C:\Users\Semen\Documents\Проекты\Skillfactory\news2\venv\lib\site-packages\django\views\generic\edit.py", line 144, in get
    return self.render_to_response(self.get_context_data())
  File "C:\Users\Semen\Documents\Проекты\Skillfactory\news2\venv\lib\site-packages\django\views\generic\edit.py", line 74, in get_context_data
    kwargs["form"] = self.get_form()
  File "C:\Users\Semen\Documents\Проекты\Skillfactory\news2\venv\lib\site-packages\django\views\generic\edit.py", line 39, in get_form
    return form_class(**self.get_form_kwargs())
TypeError: BaseModelForm.__init__() got an unexpected keyword argument 'user'
INFO 2024-01-16 23:45:38,271 autoreload C:\Users\Semen\Documents\Проекты\Skillfactory\news2\venv\project\simpleapp\forms.py changed, reloading.
INFO 2024-01-16 23:45:38,919 autoreload Watching for file changes with StatReloader
INFO 2024-01-16 23:52:12,641 autoreload Watching for file changes with StatReloader
ERROR 2024-01-16 23:52:22,426 log Internal Server Error: /subscribe/
Traceback (most recent call last):
  File "C:\Users\Semen\Documents\Проекты\Skillfactory\news2\venv\lib\site-packages\django\core\handlers\exception.py", line 55, in inner
    response = get_response(request)
  File "C:\Users\Semen\Documents\Проекты\Skillfactory\news2\venv\lib\site-packages\django\core\handlers\base.py", line 197, in _get_response
    response = wrapped_callback(request, *callback_args, **callback_kwargs)
  File "C:\Users\Semen\Documents\Проекты\Skillfactory\news2\venv\lib\site-packages\django\views\generic\base.py", line 104, in view
    return self.dispatch(request, *args, **kwargs)
  File "C:\Users\Semen\Documents\Проекты\Skillfactory\news2\venv\lib\site-packages\django\views\generic\base.py", line 143, in dispatch
    return handler(request, *args, **kwargs)
  File "C:\Users\Semen\Documents\Проекты\Skillfactory\news2\venv\lib\site-packages\django\views\generic\edit.py", line 180, in get
    return super().get(request, *args, **kwargs)
  File "C:\Users\Semen\Documents\Проекты\Skillfactory\news2\venv\lib\site-packages\django\views\generic\edit.py", line 144, in get
    return self.render_to_response(self.get_context_data())
  File "C:\Users\Semen\Documents\Проекты\Skillfactory\news2\venv\lib\site-packages\django\views\generic\edit.py", line 74, in get_context_data
    kwargs["form"] = self.get_form()
  File "C:\Users\Semen\Documents\Проекты\Skillfactory\news2\venv\lib\site-packages\django\views\generic\edit.py", line 39, in get_form
    return form_class(**self.get_form_kwargs())
TypeError: BaseModelForm.__init__() got an unexpected keyword argument 'user'
ERROR 2024-01-16 23:52:49,851 log Internal Server Error: /subscribe/
Traceback (most recent call last):
  File "C:\Users\Semen\Documents\Проекты\Skillfactory\news2\venv\lib\site-packages\django\core\handlers\exception.py", line 55, in inner
    response = get_response(request)
  File "C:\Users\Semen\Documents\Проекты\Skillfactory\news2\venv\lib\site-packages\django\core\handlers\base.py", line 197, in _get_response
    response = wrapped_callback(request, *callback_args, **callback_kwargs)
  File "C:\Users\Semen\Documents\Проекты\Skillfactory\news2\venv\lib\site-packages\django\views\generic\base.py", line 104, in view
    return self.dispatch(request, *args, **kwargs)
  File "C:\Users\Semen\Documents\Проекты\Skillfactory\news2\venv\lib\site-packages\django\views\generic\base.py", line 143, in dispatch
    return handler(request, *args, **kwargs)
  File "C:\Users\Semen\Documents\Проекты\Skillfactory\news2\venv\lib\site-packages\django\views\generic\edit.py", line 180, in get
    return super().get(request, *args, **kwargs)
  File "C:\Users\Semen\Documents\Проекты\Skillfactory\news2\venv\lib\site-packages\django\views\generic\edit.py", line 144, in get
    return self.render_to_response(self.get_context_data())
  File "C:\Users\Semen\Documents\Проекты\Skillfactory\news2\venv\lib\site-packages\django\views\generic\edit.py", line 74, in get_context_data
    kwargs["form"] = self.get_form()
  File "C:\Users\Semen\Documents\Проекты\Skillfactory\news2\venv\lib\site-packages\django\views\generic\edit.py", line 39, in get_form
    return form_class(**self.get_form_kwargs())
TypeError: BaseModelForm.__init__() got an unexpected keyword argument 'user'
INFO 2024-01-16 23:52:50,743 autoreload C:\Users\Semen\Documents\Проекты\Skillfactory\news2\venv\project\simpleapp\views.py changed, reloading.
INFO 2024-01-16 23:52:51,438 autoreload Watching for file changes with StatReloader
INFO 2024-01-16 23:54:18,250 autoreload C:\Users\Semen\Documents\Проекты\Skillfactory\news2\venv\project\simpleapp\views.py changed, reloading.
INFO 2024-01-16 23:54:18,926 autoreload Watching for file changes with StatReloader
